<?xml version="1.0" encoding="UTF-8"?>
<testsuite name="unittest.loader._FailedTest-20230321131200" tests="1" file="unittest/loader.py" time="0.001" timestamp="2023-03-21T13:12:00" failures="0" errors="1" skipped="0">
	<testcase classname="unittest.loader._FailedTest.PythonProjectDevelop.cafe.apps.menu" name="tests" time="0.001" timestamp="2023-03-21T13:12:00" file="/Users/iced_me/anaconda3/envs/flask/lib/python3.8/unittest/loader.py" line="33">
		<error type="ImportError" message="Failed to import test module: PythonProjectDevelop.cafe.apps.menu.tests
Traceback (most recent call last):
  File &quot;/Users/iced_me/anaconda3/envs/flask/lib/python3.8/unittest/loader.py&quot;, line 436, in _find_test_path
    module = self._get_module_from_name(name)
  File &quot;/Users/iced_me/anaconda3/envs/flask/lib/python3.8/unittest/loader.py&quot;, line 377, in _get_module_from_name
    __import__(name)
  File &quot;/Users/iced_me/Developer/Python/PythonProjectDevelop/cafe/apps/menu/tests.py&quot;, line 3, in &lt;module&gt;
    from cafe.apps.menu.models import Tea
ModuleNotFoundError: No module named 'cafe'
"><![CDATA[ImportError: Failed to import test module: PythonProjectDevelop.cafe.apps.menu.tests
Traceback (most recent call last):
  File "/Users/iced_me/anaconda3/envs/flask/lib/python3.8/unittest/loader.py", line 436, in _find_test_path
    module = self._get_module_from_name(name)
  File "/Users/iced_me/anaconda3/envs/flask/lib/python3.8/unittest/loader.py", line 377, in _get_module_from_name
    __import__(name)
  File "/Users/iced_me/Developer/Python/PythonProjectDevelop/cafe/apps/menu/tests.py", line 3, in <module>
    from cafe.apps.menu.models import Tea
ModuleNotFoundError: No module named 'cafe'

]]></error>
	</testcase>
</testsuite>
